2024-11-03 04:12:19,302 ERROR: Exception on /watchVideo [GET] [in C:\Users\user\PycharmProjects\MyUtilProject\venv\lib\site-packages\flask\app.py:1414]
Traceback (most recent call last):
  File "C:\Users\user\PycharmProjects\MyUtilProject\venv\lib\site-packages\flask\app.py", line 2190, in wsgi_app
    response = self.full_dispatch_request()
  File "C:\Users\user\PycharmProjects\MyUtilProject\venv\lib\site-packages\flask\app.py", line 1486, in full_dispatch_request
    rv = self.handle_user_exception(e)
  File "C:\Users\user\PycharmProjects\MyUtilProject\venv\lib\site-packages\flask_cors\extension.py", line 178, in wrapped_function
    return cors_after_request(app.make_response(f(*args, **kwargs)))
  File "C:\Users\user\PycharmProjects\MyUtilProject\venv\lib\site-packages\flask\app.py", line 1484, in full_dispatch_request
    rv = self.dispatch_request()
  File "C:\Users\user\PycharmProjects\MyUtilProject\venv\lib\site-packages\flask\app.py", line 1469, in dispatch_request
    return self.ensure_sync(self.view_functions[rule.endpoint])(**view_args)
  File "C:\Users\user\PycharmProjects\MyUtilProject\MyApp\FlaskApp\app\routes.py", line 76, in watch_video
    video_datas = get_video_datas(os.path.join(os.getenv("APP_BASE_PATH"), dir_param))
  File "C:\Users\user\PycharmProjects\MyUtilProject\MyApp\FlaskApp\app\utils.py", line 89, in get_video_datas
    container = VideoData(dirpath=use_dir, filename=path, last_time=last_time, memo=memo)
TypeError: __init__() got an unexpected keyword argument 'last_time'
2024-11-03 04:12:32,804 ERROR: Exception on /watchVideo [GET] [in C:\Users\user\PycharmProjects\MyUtilProject\venv\lib\site-packages\flask\app.py:1414]
Traceback (most recent call last):
  File "C:\Users\user\PycharmProjects\MyUtilProject\venv\lib\site-packages\flask\app.py", line 2190, in wsgi_app
    response = self.full_dispatch_request()
  File "C:\Users\user\PycharmProjects\MyUtilProject\venv\lib\site-packages\flask\app.py", line 1486, in full_dispatch_request
    rv = self.handle_user_exception(e)
  File "C:\Users\user\PycharmProjects\MyUtilProject\venv\lib\site-packages\flask_cors\extension.py", line 178, in wrapped_function
    return cors_after_request(app.make_response(f(*args, **kwargs)))
  File "C:\Users\user\PycharmProjects\MyUtilProject\venv\lib\site-packages\flask\app.py", line 1484, in full_dispatch_request
    rv = self.dispatch_request()
  File "C:\Users\user\PycharmProjects\MyUtilProject\venv\lib\site-packages\flask\app.py", line 1469, in dispatch_request
    return self.ensure_sync(self.view_functions[rule.endpoint])(**view_args)
  File "C:\Users\user\PycharmProjects\MyUtilProject\MyApp\FlaskApp\app\routes.py", line 76, in watch_video
    video_datas = get_video_datas(os.path.join(os.getenv("APP_BASE_PATH"), dir_param))
  File "C:\Users\user\PycharmProjects\MyUtilProject\MyApp\FlaskApp\app\utils.py", line 89, in get_video_datas
    container = VideoData(dirpath=use_dir, filename=path, last_time=last_time, memo=memo)
TypeError: __init__() got an unexpected keyword argument 'last_time'
2024-11-03 04:12:33,566 ERROR: Exception on /watchVideo [GET] [in C:\Users\user\PycharmProjects\MyUtilProject\venv\lib\site-packages\flask\app.py:1414]
Traceback (most recent call last):
  File "C:\Users\user\PycharmProjects\MyUtilProject\venv\lib\site-packages\flask\app.py", line 2190, in wsgi_app
    response = self.full_dispatch_request()
  File "C:\Users\user\PycharmProjects\MyUtilProject\venv\lib\site-packages\flask\app.py", line 1486, in full_dispatch_request
    rv = self.handle_user_exception(e)
  File "C:\Users\user\PycharmProjects\MyUtilProject\venv\lib\site-packages\flask_cors\extension.py", line 178, in wrapped_function
    return cors_after_request(app.make_response(f(*args, **kwargs)))
  File "C:\Users\user\PycharmProjects\MyUtilProject\venv\lib\site-packages\flask\app.py", line 1484, in full_dispatch_request
    rv = self.dispatch_request()
  File "C:\Users\user\PycharmProjects\MyUtilProject\venv\lib\site-packages\flask\app.py", line 1469, in dispatch_request
    return self.ensure_sync(self.view_functions[rule.endpoint])(**view_args)
  File "C:\Users\user\PycharmProjects\MyUtilProject\MyApp\FlaskApp\app\routes.py", line 76, in watch_video
    video_datas = get_video_datas(os.path.join(os.getenv("APP_BASE_PATH"), dir_param))
  File "C:\Users\user\PycharmProjects\MyUtilProject\MyApp\FlaskApp\app\utils.py", line 89, in get_video_datas
    container = VideoData(dirpath=use_dir, filename=path, last_time=last_time, memo=memo)
TypeError: __init__() got an unexpected keyword argument 'last_time'
2024-11-03 06:15:15,385 ERROR: Exception on /watchVideo [GET] [in C:\Users\user\PycharmProjects\MyUtilProject\venv\lib\site-packages\flask\app.py:1414]
Traceback (most recent call last):
  File "C:\Users\user\PycharmProjects\MyUtilProject\venv\lib\site-packages\flask\app.py", line 2190, in wsgi_app
    response = self.full_dispatch_request()
  File "C:\Users\user\PycharmProjects\MyUtilProject\venv\lib\site-packages\flask\app.py", line 1486, in full_dispatch_request
    rv = self.handle_user_exception(e)
  File "C:\Users\user\PycharmProjects\MyUtilProject\venv\lib\site-packages\flask_cors\extension.py", line 178, in wrapped_function
    return cors_after_request(app.make_response(f(*args, **kwargs)))
  File "C:\Users\user\PycharmProjects\MyUtilProject\venv\lib\site-packages\flask\app.py", line 1484, in full_dispatch_request
    rv = self.dispatch_request()
  File "C:\Users\user\PycharmProjects\MyUtilProject\venv\lib\site-packages\flask\app.py", line 1469, in dispatch_request
    return self.ensure_sync(self.view_functions[rule.endpoint])(**view_args)
  File "C:\Users\user\PycharmProjects\MyUtilProject\MyApp\FlaskApp\app\routes.py", line 88, in watch_video
    render_template("watchVideo.html", data=send_data)
  File "C:\Users\user\PycharmProjects\MyUtilProject\venv\lib\site-packages\flask\templating.py", line 151, in render_template
    return _render(app, template, context)
  File "C:\Users\user\PycharmProjects\MyUtilProject\venv\lib\site-packages\flask\templating.py", line 132, in _render
    rv = template.render(context)
  File "C:\Users\user\PycharmProjects\MyUtilProject\venv\lib\site-packages\jinja2\environment.py", line 1301, in render
    self.environment.handle_exception()
  File "C:\Users\user\PycharmProjects\MyUtilProject\venv\lib\site-packages\jinja2\environment.py", line 936, in handle_exception
    raise rewrite_traceback_stack(source=source)
  File "C:\Users\user\PycharmProjects\MyUtilProject\MyApp\FlaskApp\app\templates\watchVideo.html", line 1, in top-level template code
    {% extends "format.html" %}
  File "C:\Users\user\PycharmProjects\MyUtilProject\MyApp\FlaskApp\app\templates\format.html", line 68, in top-level template code
    {% block body %}
  File "C:\Users\user\PycharmProjects\MyUtilProject\MyApp\FlaskApp\app\templates\watchVideo.html", line 25, in block 'body'
    -->                {% for path in data.items %}
TypeError: 'builtin_function_or_method' object is not iterable
2024-11-03 06:18:44,378 ERROR: Exception on /watchVideo [GET] [in C:\Users\user\PycharmProjects\MyUtilProject\venv\lib\site-packages\flask\app.py:1414]
Traceback (most recent call last):
  File "C:\Users\user\PycharmProjects\MyUtilProject\venv\lib\site-packages\flask\app.py", line 2190, in wsgi_app
    response = self.full_dispatch_request()
  File "C:\Users\user\PycharmProjects\MyUtilProject\venv\lib\site-packages\flask\app.py", line 1486, in full_dispatch_request
    rv = self.handle_user_exception(e)
  File "C:\Users\user\PycharmProjects\MyUtilProject\venv\lib\site-packages\flask_cors\extension.py", line 178, in wrapped_function
    return cors_after_request(app.make_response(f(*args, **kwargs)))
  File "C:\Users\user\PycharmProjects\MyUtilProject\venv\lib\site-packages\flask\app.py", line 1484, in full_dispatch_request
    rv = self.dispatch_request()
  File "C:\Users\user\PycharmProjects\MyUtilProject\venv\lib\site-packages\flask\app.py", line 1469, in dispatch_request
    return self.ensure_sync(self.view_functions[rule.endpoint])(**view_args)
  File "C:\Users\user\PycharmProjects\MyUtilProject\MyApp\FlaskApp\app\routes.py", line 88, in watch_video
    render_template("watchVideo.html", data=send_data)
  File "C:\Users\user\PycharmProjects\MyUtilProject\venv\lib\site-packages\flask\templating.py", line 150, in render_template
    template = app.jinja_env.get_or_select_template(template_name_or_list)
  File "C:\Users\user\PycharmProjects\MyUtilProject\venv\lib\site-packages\jinja2\environment.py", line 1081, in get_or_select_template
    return self.get_template(template_name_or_list, parent, globals)
  File "C:\Users\user\PycharmProjects\MyUtilProject\venv\lib\site-packages\jinja2\environment.py", line 1010, in get_template
    return self._load_template(name, globals)
  File "C:\Users\user\PycharmProjects\MyUtilProject\venv\lib\site-packages\jinja2\environment.py", line 969, in _load_template
    template = self.loader.load(self, name, self.make_globals(globals))
  File "C:\Users\user\PycharmProjects\MyUtilProject\venv\lib\site-packages\jinja2\loaders.py", line 138, in load
    code = environment.compile(source, name, filename)
  File "C:\Users\user\PycharmProjects\MyUtilProject\venv\lib\site-packages\jinja2\environment.py", line 768, in compile
    self.handle_exception(source=source_hint)
  File "C:\Users\user\PycharmProjects\MyUtilProject\venv\lib\site-packages\jinja2\environment.py", line 936, in handle_exception
    raise rewrite_traceback_stack(source=source)
  File "C:\Users\user\PycharmProjects\MyUtilProject\MyApp\FlaskApp\app\templates\watchVideo.html", line 26, in template
    <option value="{{ path['filename'] }}" class="videoPathContainer">{{ path['filename']] }}</option>
jinja2.exceptions.TemplateSyntaxError: unexpected ']'
