2024-11-04 12:33:50,826 ERROR: Exception on /watchVideo/json [GET] [in C:\Users\user\PycharmProjects\MyUtilProject\venv\lib\site-packages\flask\app.py:1414]
Traceback (most recent call last):
  File "C:\Users\user\PycharmProjects\MyUtilProject\venv\lib\site-packages\flask\app.py", line 2190, in wsgi_app
    response = self.full_dispatch_request()
  File "C:\Users\user\PycharmProjects\MyUtilProject\venv\lib\site-packages\flask\app.py", line 1486, in full_dispatch_request
    rv = self.handle_user_exception(e)
  File "C:\Users\user\PycharmProjects\MyUtilProject\venv\lib\site-packages\flask_cors\extension.py", line 178, in wrapped_function
    return cors_after_request(app.make_response(f(*args, **kwargs)))
  File "C:\Users\user\PycharmProjects\MyUtilProject\venv\lib\site-packages\flask\app.py", line 1484, in full_dispatch_request
    rv = self.dispatch_request()
  File "C:\Users\user\PycharmProjects\MyUtilProject\venv\lib\site-packages\flask\app.py", line 1469, in dispatch_request
    return self.ensure_sync(self.view_functions[rule.endpoint])(**view_args)
  File "C:\Users\user\PycharmProjects\MyUtilProject\MyApp\FlaskApp\app\routes.py", line 99, in watch_video_json
    return jsonify(senddata)
NameError: name 'senddata' is not defined
2024-11-04 12:33:51,162 ERROR: Exception on /watchVideo/json [GET] [in C:\Users\user\PycharmProjects\MyUtilProject\venv\lib\site-packages\flask\app.py:1414]
Traceback (most recent call last):
  File "C:\Users\user\PycharmProjects\MyUtilProject\venv\lib\site-packages\flask\app.py", line 2190, in wsgi_app
    response = self.full_dispatch_request()
  File "C:\Users\user\PycharmProjects\MyUtilProject\venv\lib\site-packages\flask\app.py", line 1486, in full_dispatch_request
    rv = self.handle_user_exception(e)
  File "C:\Users\user\PycharmProjects\MyUtilProject\venv\lib\site-packages\flask_cors\extension.py", line 178, in wrapped_function
    return cors_after_request(app.make_response(f(*args, **kwargs)))
  File "C:\Users\user\PycharmProjects\MyUtilProject\venv\lib\site-packages\flask\app.py", line 1484, in full_dispatch_request
    rv = self.dispatch_request()
  File "C:\Users\user\PycharmProjects\MyUtilProject\venv\lib\site-packages\flask\app.py", line 1469, in dispatch_request
    return self.ensure_sync(self.view_functions[rule.endpoint])(**view_args)
  File "C:\Users\user\PycharmProjects\MyUtilProject\MyApp\FlaskApp\app\routes.py", line 99, in watch_video_json
    return jsonify(senddata)
NameError: name 'senddata' is not defined
2024-11-04 12:35:00,963 ERROR: Exception on /watchVideo/json [GET] [in C:\Users\user\PycharmProjects\MyUtilProject\venv\lib\site-packages\flask\app.py:1414]
Traceback (most recent call last):
  File "C:\Users\user\PycharmProjects\MyUtilProject\venv\lib\site-packages\flask\app.py", line 2190, in wsgi_app
    response = self.full_dispatch_request()
  File "C:\Users\user\PycharmProjects\MyUtilProject\venv\lib\site-packages\flask\app.py", line 1486, in full_dispatch_request
    rv = self.handle_user_exception(e)
  File "C:\Users\user\PycharmProjects\MyUtilProject\venv\lib\site-packages\flask_cors\extension.py", line 178, in wrapped_function
    return cors_after_request(app.make_response(f(*args, **kwargs)))
  File "C:\Users\user\PycharmProjects\MyUtilProject\venv\lib\site-packages\flask\app.py", line 1484, in full_dispatch_request
    rv = self.dispatch_request()
  File "C:\Users\user\PycharmProjects\MyUtilProject\venv\lib\site-packages\flask\app.py", line 1469, in dispatch_request
    return self.ensure_sync(self.view_functions[rule.endpoint])(**view_args)
  File "C:\Users\user\PycharmProjects\MyUtilProject\MyApp\FlaskApp\app\routes.py", line 99, in watch_video_json
    return jsonify(senddata)
NameError: name 'senddata' is not defined
2025-01-25 00:48:50,200 ERROR: 127.0.0.1 - - [25/Jan/2025 00:48:50] code 400, message Bad request version ('\x00\x12\x00\x10\x04\x03\x08\x04\x04\x01\x05\x03\x08\x05\x05\x01\x08\x06\x06\x01\x00') [in C:\Users\user\PycharmProjects\MyUtilProject\venv\lib\site-packages\werkzeug\_internal.py:187]
2025-02-04 13:29:49,264 ERROR: Exception on /downloadVideo [POST] [in C:\Users\user\PycharmProjects\MyUtilProject\venv\lib\site-packages\flask\app.py:1414]
Traceback (most recent call last):
  File "C:\Users\user\PycharmProjects\MyUtilProject\venv\lib\site-packages\flask\app.py", line 2190, in wsgi_app
    response = self.full_dispatch_request()
  File "C:\Users\user\PycharmProjects\MyUtilProject\venv\lib\site-packages\flask\app.py", line 1486, in full_dispatch_request
    rv = self.handle_user_exception(e)
  File "C:\Users\user\PycharmProjects\MyUtilProject\venv\lib\site-packages\flask_cors\extension.py", line 178, in wrapped_function
    return cors_after_request(app.make_response(f(*args, **kwargs)))
  File "C:\Users\user\PycharmProjects\MyUtilProject\venv\lib\site-packages\flask\app.py", line 1484, in full_dispatch_request
    rv = self.dispatch_request()
  File "C:\Users\user\PycharmProjects\MyUtilProject\venv\lib\site-packages\flask\app.py", line 1469, in dispatch_request
    return self.ensure_sync(self.view_functions[rule.endpoint])(**view_args)
  File "C:\Users\user\PycharmProjects\MyUtilProject\MyApp\FlaskApp\app\routes.py", line 95, in download_video
    download(video_id=video_id, save_dir=save_dir, quality=save_quality, start_time=start_time, end_time=end_time)
  File "C:\Users\user\PycharmProjects\MyUtilProject\MyApp\FlaskApp\app\utils.py", line 183, in download
    format_id = get_best_format(video_id, quality)
  File "C:\Users\user\PycharmProjects\MyUtilProject\MyApp\FlaskApp\app\utils.py", line 208, in get_best_format
    result = subprocess.run(command, capture_output=True, text=True)
  File "C:\Users\user\AppData\Local\Programs\Python\Python39\lib\subprocess.py", line 505, in run
    with Popen(*popenargs, **kwargs) as process:
  File "C:\Users\user\AppData\Local\Programs\Python\Python39\lib\subprocess.py", line 951, in __init__
    self._execute_child(args, executable, preexec_fn, close_fds,
  File "C:\Users\user\AppData\Local\Programs\Python\Python39\lib\subprocess.py", line 1420, in _execute_child
    hp, ht, pid, tid = _winapi.CreateProcess(executable, args,
FileNotFoundError: [WinError 2] 指定されたファイルが見つかりません。
2025-02-25 14:07:21,264 ERROR: Exception on /vmusic [GET] [in C:\Users\user\PycharmProjects\MyUtilProject\venv\lib\site-packages\flask\app.py:1414]
Traceback (most recent call last):
  File "C:\Users\user\PycharmProjects\MyUtilProject\venv\lib\site-packages\flask\app.py", line 2190, in wsgi_app
    response = self.full_dispatch_request()
  File "C:\Users\user\PycharmProjects\MyUtilProject\venv\lib\site-packages\flask\app.py", line 1486, in full_dispatch_request
    rv = self.handle_user_exception(e)
  File "C:\Users\user\PycharmProjects\MyUtilProject\venv\lib\site-packages\flask_cors\extension.py", line 178, in wrapped_function
    return cors_after_request(app.make_response(f(*args, **kwargs)))
  File "C:\Users\user\PycharmProjects\MyUtilProject\venv\lib\site-packages\flask\app.py", line 1484, in full_dispatch_request
    rv = self.dispatch_request()
  File "C:\Users\user\PycharmProjects\MyUtilProject\venv\lib\site-packages\flask\app.py", line 1469, in dispatch_request
    return self.ensure_sync(self.view_functions[rule.endpoint])(**view_args)
  File "C:\Users\user\PycharmProjects\MyUtilProject\MyApp\FlaskApp\app\routes.py", line 120, in serve_react
    return send_from_directory("static", "react/index.html")
NameError: name 'send_from_directory' is not defined
2025-02-28 01:39:04,053 ERROR: 127.0.0.1 - - [28/Feb/2025 01:39:04] code 400, message Bad request version ('\x00\x12\x00\x10\x04\x03\x08\x04\x04\x01\x05\x03\x08\x05\x05\x01\x08\x06\x06\x01\x00') [in C:\Users\user\PycharmProjects\MyUtilProject\venv\lib\site-packages\werkzeug\_internal.py:187]
2025-04-02 11:09:38,833 ERROR: 127.0.0.1 - - [02/Apr/2025 11:09:38] code 400, message Bad request version ('\x08http/1.1\x00') [in C:\Users\user\PycharmProjects\MyUtilProject\venv\lib\site-packages\werkzeug\_internal.py:187]
